<mujoco model="inspire_hand_right">
  <option iterations="50" timestep="0.001" solver="PGS" gravity="0 0 -9.81" />

  <compiler angle="radian" meshdir="meshes" eulerseq="zyx" autolimits="true" />

  <default>
    <joint limited="true" damping="0.01" armature="0.01" frictionloss="0.01" />
    <geom condim="4" contype="1" conaffinity="15" friction="0.9 0.2 0.2" solref="0.001 2" />
    <motor ctrllimited="true" />
    <equality solref="0.001 2" />
    <default class="visualgeom">
      <geom material="visualgeom" condim="1" contype="0" conaffinity="0" />
    </default>
  </default>

  <asset>
    <mesh name="right_thumb_proximal_base" content_type="model/obj" file="right_thumb_proximal_base.obj" />
    <mesh name="right_thumb_proximal" content_type="model/obj" file="right_thumb_proximal.obj" />
    <mesh name="right_thumb_intermediate" content_type="model/obj" file="right_thumb_intermediate.obj" />
    <mesh name="right_thumb_distal" content_type="model/obj" file="right_thumb_distal.obj" />
    <mesh name="right_index_proximal" content_type="model/obj" file="right_index_proximal.obj" />
    <mesh name="right_index_intermediate" content_type="model/obj" file="right_index_intermediate.obj" />
    <mesh name="right_middle_intermediate" content_type="model/obj" file="right_middle_intermediate.obj" />
    <mesh name="right_pinky_intermediate" content_type="model/obj" file="right_pinky_intermediate.obj" />
    <texture name="texplane" type="2d" builtin="checker" rgb1=".0 .0 .0" rgb2=".8 .8 .8" width="100" height="100" />
    <material name="matplane" reflectance="0." texture="texplane" texrepeat="1 1" texuniform="true" />
    <material name="visualgeom" rgba="0.5 0.9 0.2 1" />
  </asset>

  <worldbody>
    <light directional="true" diffuse="0.4 0.4 0.4" specular="0.1 0.1 0.1" pos="0 0 5.0" dir="0 0 -1" castshadow="false" />
    <light directional="true" diffuse="0.6 0.6 0.6" specular="0.2 0.2 0.2" pos="0 0 4" dir="0 0 -1" />
    <geom name="ground" type="plane" pos="0 0 0" size="100 100 0.001" quat="1 0 0 0" material="matplane" condim="3" conaffinity="15" />
    <camera name="fixed" pos="0 -3.0 0.49070000000076053" xyaxes="1 0 0 0 0 1" />
    <camera name="track" mode="trackcom" pos="0 -3.0 0.49070000000076053" xyaxes="1 0 0 0 0 1" />
    <body name="root" pos="0 0 -0.009299999999239462" quat="1 0 0 0">
      <freejoint name="root" />
      <site name="imu" size="0.01" pos="0 0 0" />
      <geom size="0.028 0.0139" pos="0 8.60444e-08 0.0136" quat="1.32679e-06 0 0 1" type="cylinder" contype="1" conaffinity="0" density="0" group="1" class="visualgeom" />
      <geom type="cylinder" rgba="" pos="0 8.60444e-08 0.0136" quat="1.32679e-06 0 0 1" />
      <geom size="0.01955 0.0101 0.0287" pos="0.0032 2.31927e-07 0.038" quat="9.38189e-07 -9.38183e-07 -0.707105 0.707109" type="box" contype="1" conaffinity="0" density="0" group="1" class="visualgeom" />
      <geom type="box" rgba="" size="0.01955 0.0101 0.0287" pos="0.0032 2.31927e-07 0.038" quat="9.38189e-07 -9.38183e-07 -0.707105 0.707109" />
      <geom size="0.01955 0.02 0.0407" pos="0.0032 4.22996e-07 0.0682" quat="9.38189e-07 -9.38183e-07 -0.707105 0.707109" type="box" contype="1" conaffinity="0" density="0" group="1" class="visualgeom" />
      <geom type="box" rgba="" size="0.01955 0.02 0.0407" pos="0.0032 4.22996e-07 0.0682" quat="9.38189e-07 -9.38183e-07 -0.707105 0.707109" />
      <geom size="0.0161 0.02 0.0407" pos="1.81486e-12 6.83927e-07 0.1081" quat="9.38189e-07 -9.38183e-07 -0.707105 0.707109" type="box" contype="1" conaffinity="0" density="0" group="1" class="visualgeom" />
      <geom type="box" rgba="" size="0.0161 0.02 0.0407" pos="1.81486e-12 6.83927e-07 0.1081" quat="9.38189e-07 -9.38183e-07 -0.707105 0.707109" />
      <geom size="0.00625 0.00555 0.00445" pos="0.00159992 -0.0308992 0.134" quat="9.38189e-07 -9.38183e-07 -0.707105 0.707109" type="box" contype="1" conaffinity="0" density="0" group="1" class="visualgeom" />
      <geom type="box" rgba="" size="0.00625 0.00555 0.00445" pos="0.00159992 -0.0308992 0.134" quat="9.38189e-07 -9.38183e-07 -0.707105 0.707109" />
      <geom size="0.00625 0.00555 0.00445" pos="0.00159997 -0.0117992 0.134" quat="9.38189e-07 -9.38183e-07 -0.707105 0.707109" type="box" contype="1" conaffinity="0" density="0" group="1" class="visualgeom" />
      <geom type="box" rgba="" size="0.00625 0.00555 0.00445" pos="0.00159997 -0.0117992 0.134" quat="9.38189e-07 -9.38183e-07 -0.707105 0.707109" />
      <geom size="0.00625 0.00555 0.00445" pos="0.00160002 0.00700084 0.134" quat="9.38189e-07 -9.38183e-07 -0.707105 0.707109" type="box" contype="1" conaffinity="0" density="0" group="1" class="visualgeom" />
      <geom type="box" rgba="" size="0.00625 0.00555 0.00445" pos="0.00160002 0.00700084 0.134" quat="9.38189e-07 -9.38183e-07 -0.707105 0.707109" />
      <geom size="0.00625 0.00555 0.00445" pos="0.00160007 0.0262008 0.134" quat="9.38189e-07 -9.38183e-07 -0.707105 0.707109" type="box" contype="1" conaffinity="0" density="0" group="1" class="visualgeom" />
      <geom type="box" rgba="" size="0.00625 0.00555 0.00445" pos="0.00160007 0.0262008 0.134" quat="9.38189e-07 -9.38183e-07 -0.707105 0.707109" />
      <body name="thumb_proximal_base" pos="0.0169601 0.0204504 0.0690999" quat="-0.707107 9.38192e-07 3.53553e-06 0.707106">
        <inertial pos="-0.0048064 0.0009382 -0.00757" quat="0.515015 0.680854 0.408023 0.323596" mass="0.0018869" diaginertia="8.66026e-08 6.8732e-08 4.94194e-08" />
        <joint name="thumb_proximal_yaw_joint" pos="0 0 0" axis="0 0 -1" range="0 1.308" actuatorfrcrange="-1 1" />
        <geom type="mesh" mesh="right_thumb_proximal_base" contype="1" conaffinity="0" density="0" group="1" class="visualgeom" />
        <geom type="mesh" rgba="" mesh="right_thumb_proximal_base" />
        <body name="thumb_proximal" pos="-0.0088099 0.010892 -0.00925" quat="0.0996843 0.0996847 0.700046 0.700044">
          <inertial pos="0.021932 0.012785 -0.0080386" quat="-0.254474 0.660716 0.251893 0.659733" mass="0.0066075" diaginertia="2.78601e-06 2.43933e-06 8.64566e-07" />
          <joint name="thumb_proximal_pitch_joint" pos="0 0 0" axis="0 0 1" range="0 0.6" actuatorfrcrange="-1 1" />
          <geom type="mesh" mesh="right_thumb_proximal" contype="1" conaffinity="0" density="0" group="1" class="visualgeom" />
          <geom type="mesh" rgba="" mesh="right_thumb_proximal" />
          <body name="thumb_intermediate" pos="0.04407 0.034553 -0.0008">
            <inertial pos="0.0095544 -0.0016282 -0.0071997" quat="0.636718 0.307389 -0.636802 0.307548" mass="0.0037847" diaginertia="4.6531e-07 4.48089e-07 2.45661e-07" />
            <joint name="thumb_intermediate_joint" pos="0 0 0" axis="0 0 1" range="0 0.8" actuatorfrcrange="-1 1" />
            <geom type="mesh" mesh="right_thumb_intermediate" contype="1" conaffinity="0" density="0" group="1" class="visualgeom" />
            <geom type="mesh" rgba="" mesh="right_thumb_intermediate" />
            <body name="thumb_distal" pos="0.020248 0.010156 -0.0012">
              <inertial pos="0.0092888 0.0049529 -0.0060033" quat="-0.266294 0.655967 0.262806 0.655537" mass="0.0033441" diaginertia="2.0026e-07 1.95247e-07 8.1593e-08" />
              <joint name="thumb_distal_joint" pos="0 0 0" axis="0 0 1" range="0 0.4" actuatorfrcrange="-1 1" />
              <geom type="mesh" mesh="right_thumb_distal" contype="1" conaffinity="0" density="0" group="1" class="visualgeom" />
              <geom type="mesh" rgba="" mesh="right_thumb_distal" />
            </body>
          </body>
        </body>
      </body>
      <body name="index_proximal" pos="-0.000285244 0.0322689 0.13653" quat="-9.21673e-07 -9.54413e-07 -0.719337 -0.694661">
        <inertial pos="0.0012259 0.011942 -0.0060001" quat="0.50867 0.49121 -0.508643 0.491172" mass="0.0042403" diaginertia="6.9398e-07 6.62871e-07 2.10909e-07" />
        <joint name="index_proximal_joint" pos="0 0 0" axis="0 0 1" range="0 1.47" actuatorfrcrange="-1 1" />
        <geom type="mesh" mesh="right_index_proximal" contype="1" conaffinity="0" density="0" group="1" class="visualgeom" />
        <geom type="mesh" rgba="" mesh="right_index_proximal" />
        <body name="index_intermediate" pos="-0.0026138 0.032026 -0.001">
          <inertial pos="0.0019697 0.019589 -0.005" quat="0.466773 0.531152 -0.466773 0.531153" mass="0.0045683" diaginertia="7.8179e-07 7.72465e-07 8.47212e-08" />
          <joint name="index_intermediate_joint" pos="0 0 0" axis="0 0 1" range="-0.04545 1.56" actuatorfrcrange="-1 1" />
          <geom type="mesh" mesh="right_index_intermediate" contype="1" conaffinity="0" density="0" group="1" class="visualgeom" />
          <geom type="mesh" rgba="" mesh="right_index_intermediate" />
        </body>
      </body>
      <body name="middle_proximal" pos="-0.000285296 0.0129509 0.1371" quat="-9.38186e-07 -9.38185e-07 -0.707106 -0.707107">
        <inertial pos="0.001297 0.011934 -0.0060001" quat="0.510131 0.489693 -0.510105 0.489653" mass="0.0042403" diaginertia="6.9397e-07 6.62865e-07 2.10915e-07" />
        <joint name="middle_proximal_joint" pos="0 0 0" axis="0 0 1" range="0 1.47" actuatorfrcrange="-1 1" />
        <geom type="mesh" mesh="right_index_proximal" contype="1" conaffinity="0" density="0" group="1" class="visualgeom" />
        <geom type="mesh" rgba="" mesh="right_index_proximal" />
        <body name="middle_intermediate" pos="-0.0024229 0.032041 -0.001">
          <inertial pos="0.001921 0.020796 -0.005" quat="0.466148 0.531627 -0.466229 0.531705" mass="0.0050396" diaginertia="9.8384e-07 9.73279e-07 9.14014e-08" />
          <joint name="middle_intermediate_joint" pos="0 0 0" axis="0 0 1" range="-0.04545 1.56" actuatorfrcrange="-1 1" />
          <geom type="mesh" mesh="right_middle_intermediate" contype="1" conaffinity="0" density="0" group="1" class="visualgeom" />
          <geom type="mesh" rgba="" mesh="right_middle_intermediate" />
        </body>
      </body>
      <body name="ring_proximal" pos="-0.000285347 -0.00628633 0.13691" quat="9.62435e-07 9.13293e-07 0.688345 0.725383">
        <inertial pos="0.001297 0.011934 -0.0060002" quat="0.510129 0.489691 -0.510107 0.489654" mass="0.0042403" diaginertia="6.9397e-07 6.62865e-07 2.10915e-07" />
        <joint name="ring_proximal_joint" pos="0 0 0" axis="0 0 1" range="0 1.47" actuatorfrcrange="-1 1" />
        <geom type="mesh" mesh="right_index_proximal" contype="1" conaffinity="0" density="0" group="1" class="visualgeom" />
        <geom type="mesh" rgba="" mesh="right_index_proximal" />
        <body name="ring_intermediate" pos="-0.0024229 0.032041 -0.001">
          <inertial pos="0.0021753 0.019567 -0.005" quat="0.469554 0.528695 -0.469554 0.528695" mass="0.0045683" diaginertia="7.8177e-07 7.72448e-07 8.4722e-08" />
          <joint name="ring_intermediate_joint" pos="0 0 0" axis="0 0 1" range="-0.04545 1.56" actuatorfrcrange="-1 1" />
          <geom type="mesh" mesh="right_index_intermediate" contype="1" conaffinity="0" density="0" group="1" class="visualgeom" />
          <geom type="mesh" rgba="" mesh="right_index_intermediate" />
        </body>
      </body>
      <body name="pinky_proximal" pos="-0.000285398 -0.0254871 0.13571" quat="9.85986e-07 8.87816e-07 0.669143 0.743134">
        <inertial pos="0.001297 0.011934 -0.0060001" quat="0.51013 0.489693 -0.510106 0.489653" mass="0.0042403" diaginertia="6.9397e-07 6.62865e-07 2.10915e-07" />
        <joint name="pinky_proximal_joint" pos="0 0 0" axis="0 0 1" range="0 1.47" actuatorfrcrange="-1 1" />
        <geom type="mesh" mesh="right_index_proximal" contype="1" conaffinity="0" density="0" group="1" class="visualgeom" />
        <geom type="mesh" rgba="" mesh="right_index_proximal" />
        <body name="pinky_intermediate" pos="-0.0024229 0.032041 -0.001">
          <inertial pos="0.0024748 0.016203 -0.0050031" quat="0.47398 0.528862 -0.469291 0.524799" mass="0.0035996" diaginertia="4.4867e-07 4.43723e-07 6.56538e-08" />
          <joint name="pinky_intermediate_joint" pos="0 0 0" axis="0 0 1" range="-0.04545 1.56" actuatorfrcrange="-1 1" />
          <geom type="mesh" mesh="right_pinky_intermediate" contype="1" conaffinity="0" density="0" group="1" class="visualgeom" />
          <geom type="mesh" rgba="" mesh="right_pinky_intermediate" />
        </body>
      </body>
    </body>
  </worldbody>

  <actuator>
    <motor name="thumb_proximal_yaw_joint" joint="thumb_proximal_yaw_joint" ctrllimited="true" ctrlrange="-1 1" gear="1" />
    <motor name="thumb_proximal_pitch_joint" joint="thumb_proximal_pitch_joint" ctrllimited="true" ctrlrange="-1 1" gear="1" />
    <motor name="thumb_intermediate_joint" joint="thumb_intermediate_joint" ctrllimited="true" ctrlrange="-1 1" gear="1" />
    <motor name="thumb_distal_joint" joint="thumb_distal_joint" ctrllimited="true" ctrlrange="-1 1" gear="1" />
    <motor name="index_proximal_joint" joint="index_proximal_joint" ctrllimited="true" ctrlrange="-1 1" gear="1" />
    <motor name="index_intermediate_joint" joint="index_intermediate_joint" ctrllimited="true" ctrlrange="-1 1" gear="1" />
    <motor name="middle_proximal_joint" joint="middle_proximal_joint" ctrllimited="true" ctrlrange="-1 1" gear="1" />
    <motor name="middle_intermediate_joint" joint="middle_intermediate_joint" ctrllimited="true" ctrlrange="-1 1" gear="1" />
    <motor name="ring_proximal_joint" joint="ring_proximal_joint" ctrllimited="true" ctrlrange="-1 1" gear="1" />
    <motor name="ring_intermediate_joint" joint="ring_intermediate_joint" ctrllimited="true" ctrlrange="-1 1" gear="1" />
    <motor name="pinky_proximal_joint" joint="pinky_proximal_joint" ctrllimited="true" ctrlrange="-1 1" gear="1" />
    <motor name="pinky_intermediate_joint" joint="pinky_intermediate_joint" ctrllimited="true" ctrlrange="-1 1" gear="1" />
  </actuator>

  <sensor>
    <actuatorpos name="thumb_proximal_yaw_joint_p" actuator="thumb_proximal_yaw_joint" />
    <actuatorvel name="thumb_proximal_yaw_joint_v" actuator="thumb_proximal_yaw_joint" />
    <actuatorfrc name="thumb_proximal_yaw_joint_f" actuator="thumb_proximal_yaw_joint" noise="0.001" />
    <actuatorpos name="thumb_proximal_pitch_joint_p" actuator="thumb_proximal_pitch_joint" />
    <actuatorvel name="thumb_proximal_pitch_joint_v" actuator="thumb_proximal_pitch_joint" />
    <actuatorfrc name="thumb_proximal_pitch_joint_f" actuator="thumb_proximal_pitch_joint" noise="0.001" />
    <actuatorpos name="thumb_intermediate_joint_p" actuator="thumb_intermediate_joint" />
    <actuatorvel name="thumb_intermediate_joint_v" actuator="thumb_intermediate_joint" />
    <actuatorfrc name="thumb_intermediate_joint_f" actuator="thumb_intermediate_joint" noise="0.001" />
    <actuatorpos name="thumb_distal_joint_p" actuator="thumb_distal_joint" />
    <actuatorvel name="thumb_distal_joint_v" actuator="thumb_distal_joint" />
    <actuatorfrc name="thumb_distal_joint_f" actuator="thumb_distal_joint" noise="0.001" />
    <actuatorpos name="index_proximal_joint_p" actuator="index_proximal_joint" />
    <actuatorvel name="index_proximal_joint_v" actuator="index_proximal_joint" />
    <actuatorfrc name="index_proximal_joint_f" actuator="index_proximal_joint" noise="0.001" />
    <actuatorpos name="index_intermediate_joint_p" actuator="index_intermediate_joint" />
    <actuatorvel name="index_intermediate_joint_v" actuator="index_intermediate_joint" />
    <actuatorfrc name="index_intermediate_joint_f" actuator="index_intermediate_joint" noise="0.001" />
    <actuatorpos name="middle_proximal_joint_p" actuator="middle_proximal_joint" />
    <actuatorvel name="middle_proximal_joint_v" actuator="middle_proximal_joint" />
    <actuatorfrc name="middle_proximal_joint_f" actuator="middle_proximal_joint" noise="0.001" />
    <actuatorpos name="middle_intermediate_joint_p" actuator="middle_intermediate_joint" />
    <actuatorvel name="middle_intermediate_joint_v" actuator="middle_intermediate_joint" />
    <actuatorfrc name="middle_intermediate_joint_f" actuator="middle_intermediate_joint" noise="0.001" />
    <actuatorpos name="ring_proximal_joint_p" actuator="ring_proximal_joint" />
    <actuatorvel name="ring_proximal_joint_v" actuator="ring_proximal_joint" />
    <actuatorfrc name="ring_proximal_joint_f" actuator="ring_proximal_joint" noise="0.001" />
    <actuatorpos name="ring_intermediate_joint_p" actuator="ring_intermediate_joint" />
    <actuatorvel name="ring_intermediate_joint_v" actuator="ring_intermediate_joint" />
    <actuatorfrc name="ring_intermediate_joint_f" actuator="ring_intermediate_joint" noise="0.001" />
    <actuatorpos name="pinky_proximal_joint_p" actuator="pinky_proximal_joint" />
    <actuatorvel name="pinky_proximal_joint_v" actuator="pinky_proximal_joint" />
    <actuatorfrc name="pinky_proximal_joint_f" actuator="pinky_proximal_joint" noise="0.001" />
    <actuatorpos name="pinky_intermediate_joint_p" actuator="pinky_intermediate_joint" />
    <actuatorvel name="pinky_intermediate_joint_v" actuator="pinky_intermediate_joint" />
    <actuatorfrc name="pinky_intermediate_joint_f" actuator="pinky_intermediate_joint" noise="0.001" />
    <framequat name="orientation" objtype="site" noise="0.001" objname="imu" />
    <gyro name="angular-velocity" site="imu" noise="0.005" cutoff="34.9" />
  </sensor>
</mujoco>